{"timestamp": "2025-09-08T14:00:03.420309", "level": "ERROR", "logger": "test", "message": "Test error occurred", "module": "logger", "function": "_log_with_context", "line": 164, "exception": {"type": "ValueError", "message": "Test exception", "traceback": ["Traceback (most recent call last):\n", "  File \"/Users/andy.huynh/working/FinBrief/finbrief-crawler/test_monitoring_system.py\", line 34, in test_logging_system\n    raise ValueError(\"Test exception\")\n", "ValueError: Test exception\n"]}, "context": {"context": "testing", "exception_type": "ValueError", "exception_message": "Test exception"}}
